Workbook

Sheet ARIYALUR
A1: ARIYALUR
A2: SR. NO. | B2: NAME OF SCHOOL | C2: PRINCIPAL/TEACHER NAME | D2: CONT NO | E2: E. MAIL ID | F2: ADDRESS | G2: STATIONS | H2: BOARD | I2: STR | J2: SEP1ST | M2: SEP 2ND | P2: DEC 1ST | S2: DEC 2ND | V2: JAN 1ST | Y2: JAN 2ND | AB2: FEB IST | AE2: FEB IIND | AH2: MAR 1ST | AK2: MAR 2ND | AN2: APR 1ST | AQ2: APR2ND | AT2: MAY 1ST | AW2: MAY 2ND | AZ2: JUN 1ST | BC2: JUN 2ND | BF2: JUL 1ST | BI2: JUL 2ND | BL2: AUG 1ST | BO2: AUG 2ND | BR2: C | BS2: SPECIMEN- GIVEN | BT2: SPECIMEN - REQ. | BU2: VISIT DETIALS & COMMENTS
C3: PH. NO. | J3: I | K3: II | L3: III | M3: I | N3: II | O3: III | P3: I | Q3: II | R3: III | S3: I | T3: II | U3: III | V3: I | W3: II | X3: III | Y3: I | Z3: II | AA3: III | AB3: I | AC3: II | AD3: III | AE3: I | AF3: II | AG3: III | AH3: I | AI3: II | AJ3: III | AK3: I | AL3: II | AM3: III | AN3: I | AO3: II | AP3: III | AQ3: I | AR3: II | AS3: III | AT3: I | AU3: II | AV3: III | AW3: I | AX3: II | AY3: III | AZ3: I | BA3: II | BB3: III | BC3: I | BD3: II | BE3: III | BF3: I | BG3: II | BH3: III | BI3: I | BJ3: II | BK3: III | BL3: I | BM3: II | BN3: III | BO3: I | BP3: II | BQ3: III
A4: =ROW()-3 -> 1 | B4: Golden gates | C4: Gomathi | G4: Ariyalur | H4: CBSE | I4: 850 | V4: P | BR4: =COUNTA(J4:BQ4) -> 1 | BS4: JAN08-Aptitude ace | BU4: JAN08-SPEC. GVN. | BV4: =IF(BR4<=0,"0",IF(BR4=1,"1",IF(BR4=2,"2",IF(BR4=3,"3",IF(BR4>=4,"4"))))) -> 1
A5: =ROW()-3 -> 2 | B5: Hans rover | C5: Jacqueline | G5: Ariyalur | H5: CBSE | V5: P | Y5: P | BR5: =COUNTA(J5:BQ5) -> 2 | BS5: JAN29-Science lab manual 9&10 | BT5: JAN08-REQ | BU5: JAN29-SPEC GVN. JAN08-SAMPLING AFTER PONGAL. | BV5: =IF(BR5<=0,"0",IF(BR5=1,"1",IF(BR5=2,"2",IF(BR5=3,"3",IF(BR5>=4,"4"))))) -> 2
A6: =ROW()-3 -> 3 | B6: RAMCO | C6: ishwarya | G6: Ariyalur | H6: CBSE | V6: P | Y6: P | BR6: =COUNTA(J6:BQ6) -> 2 | BS6: JAN08-Hindi books 1to8, grammar 1to8 | BU6: JAN29-Order finalized JAN08-SPEC. GVN. | BV6: =IF(BR6<=0,"0",IF(BR6=1,"1",IF(BR6=2,"2",IF(BR6=3,"3",IF(BR6>=4,"4"))))) -> 2
A7: =ROW()-3 -> 4 | B7: RAMAKRISHNA PUBLIC | C7: sharmila | D7: 9443193232 | E7: ramakrishnapublicschool@gmail.com | G7: Ariyalur | H7: CBSE | I7: 650 | S7: P | V7: P | BR7: =COUNTA(J7:BQ7) -> 2 | BS7: JAN08-computer books 1to8 | BT7: DEC30-REQ | BU7: JAN08-SPEC. GVN. DEC30-SAMPLING IN JAN. | BV7: =IF(BR7<=0,"0",IF(BR7=1,"1",IF(BR7=2,"2",IF(BR7=3,"3",IF(BR7>=4,"4"))))) -> 2
A9: =ROW()-4 -> 5 | B9: SAKTHI SAI | C9: Sumathi | G9: Ariyalur | H9: STATE | I9: 700 | S9: P | BR9: =COUNTA(J9:BQ9) -> 1 | BT9: DEC30-REQ | BU9: DEC30-SAMPLING IN JAN. | BV9: =IF(BR9<=0,"0",IF(BR9=1,"1",IF(BR9=2,"2",IF(BR9=3,"3",IF(BR9>=4,"4"))))) -> 1
A25: =ROW()-3 -> 22 | B25: ADITHYA BIRLA | C25: abraham | D25: 9443300262 | E25: adithyabirla@gmail.com | G25: Ariyalur | H25: CBSE | I25: 600 | S25: P | V25: P | BR25: =COUNTA(J25:BQ25) -> 2 | BS25: JAN08-Hindi,gk, computer books 1to8 | BT25: DEC30-REQ | BU25: JAN08-SPEC. GVN. DEC30-SAMPLING IN JAN. | BV25: =IF(BR25<=0,"0",IF(BR25=1,"1",IF(BR25=2,"2",IF(BR25=3,"3",IF(BR25>=4,"4"))))) -> 2
A26: =ROW()-3 -> 23 | B26: DALMIYA VIDHYA | C26: Christopherdes | D26: 8630230691 | E26: dalmiyavidyamandir@gmail.com | G26: Ariyalur | H26: CBSE | I26: 900 | S26: P | BR26: =COUNTA(J26:BQ26) -> 1 | BT26: DEC30-SAMPLE BOOK | BU26: DEC30-WANT SPEC. | BV26: =IF(BR26<=0,"0",IF(BR26=1,"1",IF(BR26=2,"2",IF(BR26=3,"3",IF(BR26>=4,"4"))))) -> 1
A27: =ROW()-3 -> 24 | B27: Christ the King | C27: Amutha rani | E27: 650 | G27: Ariyalur | H27: CBSE | I27: 650 | Y27: P | BR27: =COUNTA(J27:BQ27) -> 1 | BS27: JAN29-English, maths assignment 1to3, rise and shine term book 4&5 | BU27: JAN29-SPEC. GVN. | BV27: =IF(BR27<=0,"0",IF(BR27=1,"1",IF(BR27=2,"2",IF(BR27=3,"3",IF(BR27>=4,"4"))))) -> 1
A28: 4 | B28: RAMCO | C28: ishwarya | D28: 9710578836 | E28: ramcovidyamandir@gmail.com | G28: Ariyalur | H28: CBSE | I28: 800 | BR28: =COUNTA(J28:BQ28) -> 0 | BV28: =IF(BR28<=0,"0",IF(BR28=1,"1",IF(BR28=2,"2",IF(BR28=3,"3",IF(BR28>=4,"4"))))) -> 0

Sheet DINDIGUL
A1: DINDIGUL
A2: SR. NO. | B2: NAME OF SCHOOL | C2: PRINCIPAL/TEACHER NAME | D2: CONT NO | E2: E. MAIL ID | F2: ADDRESS | G2: STATIONS | H2: BOARD | I2: STR | J2: SEP1ST | M2: SEP 2ND | P2: OCT1ST | S2: OCT 2ND | V2: 37196 | Y2: 37561 | AB2: DEC 1ST | AE2: DEC 2ND | AH2: JAN 1ST | AK2: JAN 2ND | AN2: FEB IST | AQ2: FEB IIND | AT2: MAR 1ST | AW2: MAR 2ND | AZ2: APR 1ST | BC2: APR2ND | BF2: MAY 1ST | BI2: MAY 2ND | BL2: JUN 1ST | BO2: JUN 2ND | BR2: JUL 1ST | BU2: JUL 2ND | BX2: AUG 1ST | CA2: AUG 2ND | CD2: C | CE2: SPECIMEN- GIVEN | CF2: SPECIMEN - REQ. | CG2: VISIT DETIALS & COMMENTS
C3: PH. NO. | J3: I | K3: II | L3: III | M3: I | N3: II | O3: III | P3: I | Q3: II | R3: III | S3: I | T3: II | U3: III | V3: I | W3: II | X3: III | Y3: I | Z3: II | AA3: III | AB3: I | AC3: II | AD3: III | AE3: I | AF3: II | AG3: III | AH3: I | AI3: II | AJ3: III | AK3: I | AL3: II | AM3: III | AN3: I | AO3: II | AP3: III | AQ3: I | AR3: II | AS3: III | AT3: I | AU3: II | AV3: III | AW3: I | AX3: II | AY3: III | AZ3: I | BA3: II | BB3: III | BC3: I | BD3: II | BE3: III | BF3: I | BG3: II | BH3: III | BI3: I | BJ3: II | BK3: III | BL3: I | BM3: II | BN3: III | BO3: I | BP3: II | BQ3: III | BR3: I | BS3: II | BT3: III | BU3: I | BV3: II | BW3: III | BX3: I | BY3: II | BZ3: III | CA3: I | CB3: II | CC3: III
A4: =ROW()-3 -> 1 | B4: ST.ANTONY CONVERT | C4: SIS.prasanna | E4: stantonycovent@gmail.com | G4: Dindigul | H4: CBSE | I4: 850 | P4: P | V4: P | Y4: P | AH4: P | AK4: P | AQ4: P | CD4: =COUNTA(J4:CC4) -> 6 | CE4: JAN06-Given patterns semester books 1to5, speak and write 1to 8 | CF4: NOV-21 SMESTER BOOKS 1-5TH NOV05-REQ | CG4: FEB17-Order not finalized JAN25-Books not finalized JAN06-SPEC. GVN LST FINAL AFTER PONGAL. NOV-21 WANT SPECIMEN IN DEC END NOV05-SAMPLING NOV END. OCT14-F.UP VST. | CH4: =IF(CD4<=0,"0",IF(CD4=1,"1",IF(CD4=2,"2",IF(CD4=3,"3",IF(CD4>=4,"4"))))) -> 4
A5: =ROW()-3 -> 2 | B5: SAKTHI SAI MATRIC SCHOOL | G5: Dindigul | H5: CBSE | I5: 520 | P5: P | S5: P | V5: P | Y5: P | AH5: P | AK5: P | AL5: P | AQ5: P | CD5: =COUNTA(J5:CC5) -> 8 | CE5: JAN25-Kg books JAN06-Science 1to8, social 1to5, english 1to8 | CF5: NOV-21 NON CARE TITLES NOV05-REQ | CG5: FEB17-Order not finalized JAN25-SPEC. GVN. JAN06-SPEC. GVN. NOV-21 WANT SPECIMEN IN FEB 2ND WEEK NOV05-SAMPLING IN FEB. OCT19-SAMPLING IN JAN. OCT04-VST FOR ORDER. | CH5: =IF(CD5<=0,"0",IF(CD5=1,"1",IF(CD5=2,"2",IF(CD5=3,"3",IF(CD5>=4,"4"))))) -> 4
A6: =ROW()-3 -> 3 | B6: SUNDARAJANVIDYALAYA | C6: angalaeswari | D6: 0451-2471700 | E6: soundaraja2002@yahoo.com | G6: Dindigul | H6: CBSE | I6: 900 | P6: P | Z6: P | AH6: P | AQ6: P | CD6: =COUNTA(J6:CC6) -> 4 | CE6: JAN06-Social studies 1to8, science 1to8, maths 6to8 | CF6: NOV-21 REQ 6-8TH BOOKS OCT14-REQ | CG6: FEB17-Order not finalized JAN06-SPEC. GVN. NOV-21 WANT SAMPLING IN DEC END OCT14-SAMPLING NOV END. | CH6: =IF(CD6<=0,"0",IF(CD6=1,"1",IF(CD6=2,"2",IF(CD6=3,"3",IF(CD6>=4,"4"))))) -> 4
A8: =ROW()-4 -> 4 | B8: HOLY CROSS | C8: father.jayaraj | D8: 7667267010 | E8: hcms2020@gmai.com | G8: Dindigul | H8: STATE | I8: 1100 | P8: P | S8: P | Y8: P | AH8: P | CD8: =COUNTA(J8:CC8) -> 4 | CF8: JAN06-REQ NOV-21 REQ | CG8: JAN06-January end wanted NOV-21 WANT SAMPLING IN JAN END OCT19-SAMPLING IN JAN. OCT04-VST FOR ORDER. | CH8: =IF(CD8<=0,"0",IF(CD8=1,"1",IF(CD8=2,"2",IF(CD8=3,"3",IF(CD8>=4,"4"))))) -> 4
A64: =ROW()-3 -> 61 | B64: ST. JOHNPAULS | C64: mumtaj | D64: 6381039699 | E64: stjohnpaulsacademy@gmail.com | G64: Dindigul | H64: CBSE | I64: 500 | P64: P | AQ64: P | CD64: =COUNTA(J64:CC64) -> 2 | CF64: OCT14-REQ | CG64: FEB17-Last year order no changes OCT14-SAMPLING IN DEC. | CH64: =IF(CD64<=0,"0",IF(CD64=1,"1",IF(CD64=2,"2",IF(CD64=3,"3",IF(CD64>=4,"4"))))) -> 2
A65: =ROW()-3 -> 62 | B65: ST. PAUL CBSE SCHOOL | G65: Dindigul | H65: CBSE | V65: P | CD65: =COUNTA(J65:CC65) -> 1 | CG65: NOV05-DISCUSS OUR TITLES. | CH65: =IF(CD65<=0,"0",IF(CD65=1,"1",IF(CD65=2,"2",IF(CD65=3,"3",IF(CD65>=4,"4"))))) -> 1
A66: =ROW()-3 -> 63 | B66: VIDYA PARTHI | E66: soundaraja2002@yahoo.com | G66: Dindigul | H66: CBSE | Y66: P | CD66: =COUNTA(J66:CC66) -> 1 | CF66: NOV-21 NON CARE TITLE | CG66: NOV-21 WANT SAMPLING IN DEC END | CH66: =IF(CD66<=0,"0",IF(CD66=1,"1",IF(CD66=2,"2",IF(CD66=3,"3",IF(CD66>=4,"4"))))) -> 1

Sheet KARUR
A1: KARUR
A2: SR. NO. | B2: NAME OF SCHOOL | C2: PRINCIPAL/TEACHER NAME | D2: CONT NO | E2: E. MAIL ID | F2: ADDRESS | G2: STATIONS | H2: BOARD | I2: STR | J2: SEP1ST | M2: SEP 2ND | P2: OCT1ST | S2: OCT 2ND | V2: 37196 | Y2: 37561 | AB2: DEC 1ST | AE2: DEC 2ND | AH2: JAN 1ST | AK2: JAN 2ND | AN2: FEB IST | AQ2: FEB IIND | AT2: MAR 1ST | AW2: MAR 2ND | AZ2: APR 1ST | BC2: APR2ND | BF2: MAY 1ST | BI2: MAY 2ND | BL2: JUN 1ST | BO2: JUN 2ND | BR2: JUL 1ST | BU2: JUL 2ND | BX2: AUG 1ST | CA2: AUG 2ND | CD2: C | CE2: SPECIMEN- GIVEN | CF2: SPECIMEN - REQ. | CG2: VISIT DETIALS & COMMENTS
C3: PH. NO. | J3: I | K3: II | L3: III | M3: I | N3: II | O3: III | P3: I | Q3: II | R3: III | S3: I | T3: II | U3: III | V3: I | W3: II | X3: III | Y3: I | Z3: II | AA3: III | AB3: I | AC3: II | AD3: III | AE3: I | AF3: II | AG3: III | AH3: I | AI3: II | AJ3: III | AK3: I | AL3: II | AM3: III | AN3: I | AO3: II | AP3: III | AQ3: I | AR3: II | AS3: III | AT3: I | AU3: II | AV3: III | AW3: I | AX3: II | AY3: III | AZ3: I | BA3: II | BB3: III | BC3: I | BD3: II | BE3: III | BF3: I | BG3: II | BH3: III | BI3: I | BJ3: II | BK3: III | BL3: I | BM3: II | BN3: III | BO3: I | BP3: II | BQ3: III | BR3: I | BS3: II | BT3: III | BU3: I | BV3: II | BW3: III | BX3: I | BY3: II | BZ3: III | CA3: I | CB3: II | CC3: III
A4: =ROW()-3 -> 1 | B4: KSV GROUP | C4: padmanaban | E4: ksvgroupschools@gmail.com | G4: Karur | H4: CBSE | I4: 1000 | M4: P | S4: P | AB4: P | AE4: P | AH4: P | BU4: P | CD4: =COUNTA(J4:CC4) -> 6 | CE4: DEC11-1 to 5 rise and shine term book | CF4: SEP26-REQ | CG4: JULY24-follow up JAN02-Order follow up DEC17-Books not decided DEC11-SPEC. GVN. OCT16-VST NOV END. SEP26-SAMPLING IN MARCH. | CH4: =IF(CD4<=0,"0",IF(CD4=1,"1",IF(CD4=2,"2",IF(CD4=3,"3",IF(CD4>=4,"4"))))) -> 4
A5: =ROW()-3 -> 2 | B5: LITTLE FLOWER | C5: Binu joseph | D5: 9751205906 | E5: littleflowercst@gmail.com | G5: Karur | H5: CBSE | I5: 800 | M5: P | P5: P | V5: P | AA5: P | AB5: P | AE5: P | AN5: P | AQ5: P | BL5: P | BO5: P | BR5: P | BS5: P | BU5: P | CD5: =COUNTA(J5:CC5) -> 13 | CE5: FEB14-Speak and write 1to8 | CF5: JUN18-English DEC17-REQ DEC11-REQ NOV-26 NONCARE BOOK NOV11-REQ SEP26-REQ | CG5: JULY24-General visit JULY10-Visit school for second follow up JULY02-General visit JUN18-WANT SPEC. JUN06-General visit FEB24-No changes for this year FEB14-SPEC. GVN. DEC17-SAMPLING JAN END. DEC11-Books wanted on January 2nd week NOV-26 WANT SAMPLING NOV11-SAMPLING IN DEC. OCT07-VST FOR BOOK INCHARGE. SEP26-SAPLING IN MARCH. | CH5: =IF(CD5<=0,"0",IF(CD5=1,"1",IF(CD5=2,"2",IF(CD5=3,"3",IF(CD5>=4,"4"))))) -> 4
A6: =ROW()-3 -> 3 | B6: LNVN | C6: mumtaj | D6: 6381211244 | E6: lnvnindia@yahoo.com | G6: Karur | H6: CBSE | I6: 800 | S6: P | AA6: P | AB6: P | AK6: P | AT6: P | AW6: P | AZ6: P | BF6: P | CD6: =COUNTA(J6:CC6) -> 8 | CE6: APR09-Speak and write 1to8, mili Tamil handwriting 1to5 MAR07-Social studies 1to5 JAN28-Gk , computer, | CF6: DEC11-REQ NOV-26 NON CARE | CG6: MAY12-General visit APR09-SPEC. GVN. MAR17-March end only decided MAR07-SPEC. GVN. JAN28-SPEC. GVN. DEC11-SAMPLING IN FEB. NOV-26 WANT SAMPLING IN FEB OCT16-VST IN DEC. | CH6: =IF(CD6<=0,"0",IF(CD6=1,"1",IF(CD6=2,"2",IF(CD6=3,"3",IF(CD6>=4,"4"))))) -> 4
A7: =ROW()-3 -> 4 | B7: STAR SCHOOL | G7: Karur | H7: CBSE | P7: P | S7: P | V7: P | Y7: P | AB7: P | AE7: P | AF7: P | AH7: P | AW7: P | BI7: P | BL7: P | BR7: P | BS7: P | BU7: P | BX7: P | CD7: =COUNTA(J7:CC7) -> 15 | CE7: MAR17-Rise and shine 1std term book and kg books DEC11-Patterns semester 1 to 5 | CF7: NOV-20 REQ NOV04-REQ OCT07-REQ | CG7: AUG08-General visit JULY24-Visit school for follow up JULY10-School visit for follow up JULY02-Visit school for follow up JUN06-General visit MAY28-General visit MAR17-SPEC. GVN. JAN02-Books not finalized DEC23-Books are not finalized DEC17-Visit about selection satus DEC11-SPEC. GVN. NOV-20 WANT SPECIMEN IN DEC END NOV04-SAMPLING DEC MNTH. OCT16-VST NOV END. OCT07-SAMPLING IN NOV. | CH7: =IF(CD7<=0,"0",IF(CD7=1,"1",IF(CD7=2,"2",IF(CD7=3,"3",IF(CD7>=4,"4"))))) -> 4
A8: =ROW()-3 -> 5 | B8: Tnpl | C8: Samiappan | E8: 1000 | G8: Karur | H8: CBSE | AT8: P | AZ8: P | BC8: P | BL8: P | CD8: =COUNTA(J8:CC8) -> 4 | CG8: JUN06-General visit APR25-DISCUSS ABUT FINALISED. APR09-Order is under process MAR06-Order is going under process | CH8: =IF(CD8<=0,"0",IF(CD8=1,"1",IF(CD8=2,"2",IF(CD8=3,"3",IF(CD8>=4,"4"))))) -> 4
A9: =ROW()-3 -> 6 | B9: SANKARA | C9: Jayanthi | E9: 1500 | G9: Karur | H9: CBSE | I9: 1500 | AE9: P | AH9: P | AQ9: P | AT9: P | AW9: P | AZ9: P | BC9: P | BR9: P | BS9: P | BU9: P | CD9: =COUNTA(J9:CC9) -> 10 | CE9: APR09-Modern Science 6to8, school maths 6to8. MAR06-Happy faces ABC | CF9: JAN02-REQ | CG9: JULY24-General visit JULY10-Visit school for follow up JULY02-General visit APR26-ORDER FINALISED. APR25-ORDER F.UP VST. APR09-SPEC. GVN. MAR17-Teacher are seeing under process MAR06-SPEC. GVN. FEB24-School visit and collect details JAN02- January 2nd week DEC23-VST AFTER PONGAL. | CH9: =IF(CD9<=0,"0",IF(CD9=1,"1",IF(CD9=2,"2",IF(CD9=3,"3",IF(CD9>=4,"4"))))) -> 4
A10: =ROW()-3 -> 7 | B10: VENUS GLOBAL | C10: sreenivasan | D10: 735887888 | E10: venusglobalcampus@gamil.com | G10: Karur | H10: CBSE | I10: 900 | M10: P | P10: P | S10: P | V10: P | Y10: P | AB10: P | AE10: P | AF10: P | AH10: P | AK10: P | AN10: P | AQ10: P | AT10: P | AW10: P | AZ10: P | BC10: P | BF10: P | BG10: P | BI10: P | BO10: P | BR10: P | BX10: P | CD10: =COUNTA(J10:CC10) -> 22 | CE10: APR09-Saras hindi 4and 5 FEB14-Saras hindi 3to8 JAN28-hindi 1&2, speak and write 1to8 DEC11-Happy faces lkg,ukg | CF10: NOV-20 KEY BOOK NOV04-REQ SEP26-REQ | CG10: AUG08-General visit JULY10-General visit JUN18-follow up MAY28-follow up MAY12-Payment visit MAY05-Order finalized APR25-NO CHANGE. APR09-SPEC. GVN. MAR17-Order finished MAR06-Order finished FEB24- order follow up FEB14-SPEC. GVN. JAN28-SPEC. GVN. JAN02-Visit for order status DEC23-Visit for order status DEC17-Visit about details of selection DEC11-SPEC. GVN. NOV-20 WANT SAMPLING IN DEC 2ND WEEK NOV04-SAMPLING DEC 2ND WEEK. OCT16-ORDER DISCUSSION. OCT07-F.UP VST. SEP26-SAMPLING IN JAN. | CH10: =IF(CD10<=0,"0",IF(CD10=1,"1",IF(CD10=2,"2",IF(CD10=3,"3",IF(CD10>=4,"4"))))) -> 4
A12: =ROW()-4 -> 8 | B12: AKSHARA YOUNG KIDS | G12: Karur | H12: STATE | P12: P | S12: P | V12: P | AA12: P | CD12: =COUNTA(J12:CC12) -> 4 | CF12: NOV-26 REQ NOV11-REQ | CG12: NOV-26 WANT SAMPLING IN JAN NOV11-SAMPLING IN JAN. OCT16-VST & MEET INCHANEG. OCT07-F.UP VST. | CH12: =IF(CD12<=0,"0",IF(CD12=1,"1",IF(CD12=2,"2",IF(CD12=3,"3",IF(CD12>=4,"4"))))) -> 4
A13: =ROW()-4 -> 9 | B13: VETHI VINAYAKA | G13: Karur | H13: STATE | V13: P | AA13: P | CD13: =COUNTA(J13:CC13) -> 2 | CF13: NOV-21 REQ NOV11-REQ | CG13: NOV-26 WANT SAMPLING IN JAN NOV11-SAMPLING IN DEC END. | CH13: =IF(CD13<=0,"0",IF(CD13=1,"1",IF(CD13=2,"2",IF(CD13=3,"3",IF(CD13>=4,"4"))))) -> 2
A14: =ROW()-4 -> 10 | B14: VETRIVINAYAGA | C14: Samiappan | E14: 850 | G14: Karur | H14: STATE | I14: 850 | AE14: P | AK14: P | AN14: P | AQ14: P | AZ14: P | BL14: P | BX14: P | CD14: =COUNTA(J14:CC14) -> 7 | CE14: FEB14-Speak and write 1to8,smart english 6&7, hindi chandhan 1to8. | CG14: AUG08-General visit JUN06-General visit APR09-Order finalized FEB24-Not finalized FEB14-SPEC. GVN. JAN28- Lead school confirmed. DEC23-VST AFTER PONGAL. | CH14: =IF(CD14<=0,"0",IF(CD14=1,"1",IF(CD14=2,"2",IF(CD14=3,"3",IF(CD14>=4,"4"))))) -> 4
A15: =ROW()-4 -> 11 | B15: SARASWATI VIDYALAYA | G15: Karur | H15: STATE | V15: P | AN15: P | AT15: P | AW15: P | AZ15: P | BF15: P | BI15: P | BO15: P | BX15: P | CD15: =COUNTA(J15:CC15) -> 9 | CE15: MAR12-Rise and shine kg books with out Tamil, enjoy with colour Ato5 MAR03-Rise and shine termbook (kg to 5) | CG15: AUG08-General visit JUN18-General visit MAY28-Order finished MAY05-Order finished APR07-Order not finalized MAR17-School visit for order status MAR12-SPEC. GVN. MAR03-SPEC. GVN. NOV04-DISCUSS WITH BOOK INCHARGE. | CH15: =IF(CD15<=0,"0",IF(CD15=1,"1",IF(CD15=2,"2",IF(CD15=3,"3",IF(CD15>=4,"4"))))) -> 4
A16: =ROW()-4 -> 12 | B16: KVBOA MATRIC SCHOOL | G16: Karur | H16: STATE | Y16: P | AH16: P | AK16: P | AN16: P | BF16: P | BO16: P | CD16: =COUNTA(J16:CC16) -> 6 | CE16: FEB14-Know it now gk 1to4 JAN02-Rise and shine kg books | CF16: NOV-20 REQ | CG16: JUN18-General visit MAY12-Follow up FEB14-SPEC. GVN. JAN28-Books not finalized after February JAN02-SPEC. GVN. NOV-20 WANT SAMPLING IN FEB | CH16: =IF(CD16<=0,"0",IF(CD16=1,"1",IF(CD16=2,"2",IF(CD16=3,"3",IF(CD16>=4,"4"))))) -> 4
A17: =ROW()-4 -> 13 | B17: RAMAKRISHNA | C17: ganeshan | D17: 9698013222 | E17: ramakrishnamatric@gmail.com | G17: Karur | H17: STATE | I17: 700 | S17: P | V17: P | AE17: P | AN17: P | AQ17: P | AT17: P | AU17: P | BC17: P | BF17: P | BG17: P | BI17: P | BR17: P | BU17: P | BX17: P | CD17: =COUNTA(J17:CC17) -> 14 | CE17: MAY05-Easycomputer1to8, AI computer 1to8, MAR06-Creative hands Ato8,saras hindi 1to8 FEB24-Basic english grammar and composition 1to5 FEB14-Speak and write 1to8, Rashmi hindi 1to8, computer genius 1to8 | CF17: DEC17-REQ NOV04-REQ | CG17: AUG08-General visit JULY24-taking return books JULY02-payment and follow up MAY28-payment visit MAY12-Order finalized MAY05-SPEC. GVN. APR25-WANT COMPUTER BOOKS. MAR07-Order finished MAR06-SPEC. GVN. FEB24-SPEC. GVNB. FEB14-SPEC. GVN. DEC17-Books wanted January end NOV04-SAMPLING FEB MNTH. OCT19-VST IN FEB. | CH17: =IF(CD17<=0,"0",IF(CD17=1,"1",IF(CD17=2,"2",IF(CD17=3,"3",IF(CD17>=4,"4"))))) -> 4
A51: =ROW()-4 -> 47 | B51: CHARAN MAT SCHOOL | C51: MR. UDHAYA KUMAR | G51: KARUR | H51: STATE | I51: 800 | M51: P | P51: P | S51: P | CD51: =COUNTA(J51:CC51) -> 3 | CF51: OCT29-REQ SEP26-REQ | CG51: OCT29-SAMPLING IN JAN. OCT07-VST FOR DISCUSSION. SEP26-SAMPLING IN FEB. | CH51: =IF(CD51<=0,"0",IF(CD51=1,"1",IF(CD51=2,"2",IF(CD51=3,"3",IF(CD51>=4,"4"))))) -> 3
A52: =ROW()-4 -> 48 | B52: MALAR | C52: Janani | E52: 650 | G52: Karur | H52: STATE | I52: 650 | AT52: P | CD52: =COUNTA(J52:CC52) -> 1 | CG52: MAR07-ORDER UNDER PROCES. | CH52: =IF(CD52<=0,"0",IF(CD52=1,"1",IF(CD52=2,"2",IF(CD52=3,"3",IF(CD52>=4,"4"))))) -> 1
A53: =ROW()-4 -> 49 | B53: STAR MATRIC SCHOOL | G53: KARUR | H53: STATE | V53: P | CD53: =COUNTA(J53:CC53) -> 1 | CF53: NOV11-REQ | CG53: NOV11-SAMPLING IN MARCH. | CH53: =IF(CD53<=0,"0",IF(CD53=1,"1",IF(CD53=2,"2",IF(CD53=3,"3",IF(CD53>=4,"4"))))) -> 1
A54: =ROW()-4 -> 50 | B54: MALAR | E54: 650 | G54: Karur | H54: STATE | AE54: P | CD54: =COUNTA(J54:CC54) -> 1 | CF54: DEC23-REQ | CG54: DEC23-SAMPLING IN JAN. | CH54: =IF(CD54<=0,"0",IF(CD54=1,"1",IF(CD54=2,"2",IF(CD54=3,"3",IF(CD54>=4,"4"))))) -> 1
A55: =ROW()-4 -> 51 | B55: LOTUS KIDS | G55: KARUR | H55: STATE | Y55: P | CD55: =COUNTA(J55:CC55) -> 1 | CF55: NOV-20 REQ | CG55: NOV-20 WANT SAMPLING JAN FIRST WEEK | CH55: =IF(CD55<=0,"0",IF(CD55=1,"1",IF(CD55=2,"2",IF(CD55=3,"3",IF(CD55>=4,"4"))))) -> 1
A57: =ROW()-3 -> 54 | B57: VIJAY VIDYALAYA | G57: KARUR | H57: CBSE | V57: P | CD57: =COUNTA(J57:CC57) -> 1 | CG57: NOV04-DISCUSS OUR TITLES. | CH57: =IF(CD57<=0,"0",IF(CD57=1,"1",IF(CD57=2,"2",IF(CD57=3,"3",IF(CD57>=4,"4"))))) -> 1
A58: =ROW()-3 -> 55 | B58: TNPL CBSE | G58: KARUR | H58: CBSE | V58: P | AA58: P | AK58: P | AN58: P | CD58: =COUNTA(J58:CC58) -> 4 | CE58: FEB14-Speak and write 1to8, inners circle 1to8, hindi saras hindi 1to5, computer genius 1to8 JAN28-Speak and write 1to8, gk 1to8, grammar 1to8, assignment 1to3 english, maths | CF58: NOV-26 LKG, UKG NOV11-REQ | CG58: FEB14-SPEC. GVN. JAN28-SPEC. GVN. NOV-26 WANT SAMPLING IN DEC NOV11-SAMPLING IN JAN. | CH58: =IF(CD58<=0,"0",IF(CD58=1,"1",IF(CD58=2,"2",IF(CD58=3,"3",IF(CD58>=4,"4"))))) -> 4

Sheet MAYILADUTHURAI
A1: MAYILADUTHURAI
A2: SR. NO. | B2: NAME OF SCHOOL | C2: PRINCIPAL/TEACHER NAME | D2: CONT NO | E2: E. MAIL ID | F2: ADDRESS | G2: STATIONS | H2: BOARD | I2: STR | J2: SEP1ST | M2: SEP 2ND | P2: OCT1ST | S2: OCT 2ND | V2: 37196 | Y2: 37561 | AB2: DEC 1ST | AE2: DEC 2ND | AH2: JAN 1ST | AK2: JAN 2ND | AN2: FEB IST | AQ2: FEB IIND | AT2: MAR 1ST | AW2: MAR 2ND | AZ2: APR 1ST | BC2: APR2ND | BF2: MAY 1ST | BI2: MAY 2ND | BL2: JUN 1ST | BO2: JUN 2ND | BR2: JUL 1ST | BU2: JUL 2ND | BX2: AUG 1ST | CA2: AUG 2ND | CD2: C | CE2: SPECIMEN- GIVEN | CF2: SPECIMEN - REQ. | CG2: VISIT DETIALS & COMMENTS
C3: PH. NO. | J3: I | K3: II | L3: III | M3: I | N3: II | O3: III | P3: I | Q3: II | R3: III | S3: I | T3: II | U3: III | V3: I | W3: II | X3: III | Y3: I | Z3: II | AA3: III | AB3: I | AC3: II | AD3: III | AE3: I | AF3: II | AG3: III | AH3: I | AI3: II | AJ3: III | AK3: I | AL3: II | AM3: III | AN3: I | AO3: II | AP3: III | AQ3: I | AR3: II | AS3: III | AT3: I | AU3: II | AV3: III | AW3: I | AX3: II | AY3: III | AZ3: I | BA3: II | BB3: III | BC3: I | BD3: II | BE3: III | BF3: I | BG3: II | BH3: III | BI3: I | BJ3: II | BK3: III | BL3: I | BM3: II | BN3: III | BO3: I | BP3: II | BQ3: III | BR3: I | BS3: II | BT3: III | BU3: I | BV3: II | BW3: III | BX3: I | BY3: II | BZ3: III | CA3: I | CB3: II | CC3: III
A4: 1 | B4: ALAGU JOTHI ACADEMY | C4: Mr Noel | D4: 8754576209 | E4: aja@gmail.com | G4: Mayiladuthurai | H4: CBSE | I4: 1060 | AB4: P | AW4: P | CD4: =COUNTA(J4:CC4) -> 2 | CF4: DEC06-Ncert work book | CG4: MAR21-Last year order no changes DEC06-WANT SPEC. | CH4: =IF(CD4<=0,"0",IF(CD4=1,"1",IF(CD4=2,"2",IF(CD4=3,"3",IF(CD4>=4,"4"))))) -> 2
A5: 2 | B5: GOOD SEMARITAN SCHOOL | C5: Ms Jasmine | D5: 9444984472 | E5: info@gspschool.org | G5: Mayiladuthurai | H5: CBSE | I5: 1174 | AB5: P | CD5: =COUNTA(J5:CC5) -> 1 | CE5: DEC06-Kg books, hindi books,gk, grammar | CG5: DEC06-SPEC. GVN. | CH5: =IF(CD5<=0,"0",IF(CD5=1,"1",IF(CD5=2,"2",IF(CD5=3,"3",IF(CD5>=4,"4"))))) -> 1
A7: 3 | B7: GURNANAK SAMANDHAR MATRIC | C7: Mr.Saravanan | D7: 9443746803 | G7: Mayiladuthurai | H7: STATE | I7: 3600 | AB7: P | AW7: P | CD7: =COUNTA(J7:CC7) -> 2 | CE7: MAR21-Speak and write 1to8 know it now gk 1to5, | CF7: DEC06-REQ | CG7: MAR21-SPEC. GVN. DEC06-SAMPLING JAN END. | CH7: =IF(CD7<=0,"0",IF(CD7=1,"1",IF(CD7=2,"2",IF(CD7=3,"3",IF(CD7>=4,"4"))))) -> 2
A8: 4 | B8: RAJ MATRIC SCHOOL | C8: Mr Venkatraman | D8: 04364-224488 | E8: rajmatricmayilai@gmail.com | G8: Mayiladuthurai | H8: STATE | I8: 1800 | AB8: P | AW8: P | CD8: =COUNTA(J8:CC8) -> 2 | CE8: MAR21-Favourite Gk 1to8,my cursive lines Ato5, Tamil handwriting 1to5 | CF8: DEC06-REQ | CG8: MAR21-SPEC. GVN. DEC06-SAMPLING AFTER PONGAL. | CH8: =IF(CD8<=0,"0",IF(CD8=1,"1",IF(CD8=2,"2",IF(CD8=3,"3",IF(CD8>=4,"4"))))) -> 2
A9: 5 | B9: VIVEKANANDA MATRIC SCHOOL | C9: Mr Ramesh | D9: 04364-270595 | E9: vmhsssirkali@gmail.com | G9: Mayiladuthurai | H9: STATE | I9: 2500 | AB9: P | CD9: =COUNTA(J9:CC9) -> 1 | CE9: DEC06-Term books, computer, hindi books | CG9: DEC06-SPEC. GVN. | CH9: =IF(CD9<=0,"0",IF(CD9=1,"1",IF(CD9=2,"2",IF(CD9=3,"3",IF(CD9>=4,"4"))))) -> 1

Sheet NAGAPATTINUM
A1: NAGAPATTINAM
A2: SR. NO. | B2: NAME OF SCHOOL | C2: PRINCIPAL/TEACHER NAME | D2: CONT NO | E2: E. MAIL ID | F2: ADDRESS | G2: STATIONS | H2: BOARD | I2: STR | J2: SEP1ST | M2: SEP 2ND | P2: OCT1ST | S2: OCT 2ND | V2: 37196 | Y2: 37561 | AB2: DEC 1ST | AE2: DEC 2ND | AH2: JAN 1ST | AK2: JAN 2ND | AN2: FEB IST | AQ2: FEB IIND | AT2: MAR 1ST | AW2: MAR 2ND | AZ2: APR 1ST | BC2: APR2ND | BF2: MAY 1ST | BI2: MAY 2ND | BL2: JUN 1ST | BO2: JUN 2ND | BR2: JUL 1ST | BU2: JUL 2ND | BX2: AUG 1ST | CA2: AUG 2ND | CD2: C | CE2: SPECIMEN- GIVEN | CF2: SPECIMEN - REQ. | CG2: VISIT DETIALS & COMMENTS
C3: PH. NO. | J3: I | K3: II | L3: III | M3: I | N3: II | O3: III | P3: I | Q3: II | R3: III | S3: I | T3: II | U3: III | V3: I | W3: II | X3: III | Y3: I | Z3: II | AA3: III | AB3: I | AC3: II | AD3: III | AE3: I | AF3: II | AG3: III | AH3: I | AI3: II | AJ3: III | AK3: I | AL3: II | AM3: III | AN3: I | AO3: II | AP3: III | AQ3: I | AR3: II | AS3: III | AT3: I | AU3: II | AV3: III | AW3: I | AX3: II | AY3: III | AZ3: I | BA3: II | BB3: III | BC3: I | BD3: II | BE3: III | BF3: I | BG3: II | BH3: III | BI3: I | BJ3: II | BK3: III | BL3: I | BM3: II | BN3: III | BO3: I | BP3: II | BQ3: III | BR3: I | BS3: II | BT3: III | BU3: I | BV3: II | BW3: III | BX3: I | BY3: II | BZ3: III | CA3: I | CB3: II | CC3: III
A4: =ROW()-3 -> 1 | B4: J JEYA MATRIC HR SEC SCHOOL | C4: Ms Henna bashkar | G4: Nagapattinam | H4: STATE | I4: 800 | AN4: P | BC4: P | CD4: =COUNTA(J4:CC4) -> 2 | CE4: FEB12-Easy Computer 1to8, know it now gk 1to8, speak and write 1to5 | CF4: FEB12-Kg term book | CG4: APR18- No changes last year order FEB12-SPEC. GVN WANT MORE. | CH4: =IF(CD4<=0,"0",IF(CD4=1,"1",IF(CD4=2,"2",IF(CD4=3,"3",IF(CD4>=4,"4"))))) -> 2
A5: =ROW()-3 -> 2 | B5: NAGORE CRECENT MATRIC SCHOOL | C5: MS. RAFIA | G5: Nagapattinam | H5: STATE | I5: 550 | AN5: P | BD5: P | CD5: =COUNTA(J5:CC5) -> 2 | CE5: FEB12-Non core books given computer,gk , | CG5: APR18-order follow up FEB12-SPEC. GVN. | CH5: =IF(CD5<=0,"0",IF(CD5=1,"1",IF(CD5=2,"2",IF(CD5=3,"3",IF(CD5>=4,"4"))))) -> 2
A6: =ROW()-3 -> 3 | B6: NAGORE MODERN MATRIC SCHOOL | C6: Ms Bennet | G6: Nagapattinam | H6: STATE | I6: 750 | AN6: P | BC6: P | CD6: =COUNTA(J6:CC6) -> 2 | CE6: APR18-Tamil handwriting 1to5, enjoy with colour Ato5 | CF6: FEB12-Kg books wanted | CG6: APR18-SPEC. GVN. FEB12-WANT SPEC. | CH6: =IF(CD6<=0,"0",IF(CD6=1,"1",IF(CD6=2,"2",IF(CD6=3,"3",IF(CD6>=4,"4"))))) -> 2

Sheet THANJUR
A1: THANJUR
A2: SR. NO. | B2: NAME OF SCHOOL | C2: PRINCIPAL/TEACHER NAME | D2: CONT NO | E2: E. MAIL ID | F2: ADDRESS | G2: STATIONS | H2: BOARD | I2: STR | J2: SEP1ST | M2: SEP 2ND | P2: OCT1ST | S2: OCT 2ND | V2: 37196 | Y2: 37561 | AB2: DEC 1ST | AE2: DEC 2ND | AH2: JAN 1ST | AK2: JAN 2ND | AN2: FEB IST | AQ2: FEB IIND | AT2: MAR 1ST | AW2: MAR 2ND | AZ2: APR 1ST | BC2: APR2ND | BF2: MAY 1ST | BI2: MAY 2ND | BL2: JUN 1ST | BO2: JUN 2ND | BR2: JUL 1ST | BU2: JUL 2ND | BX2: AUG 1ST | CA2: AUG 2ND | CD2: C | CE2: SPECIMEN- GIVEN | CF2: SPECIMEN - REQ. | CG2: VISIT DETIALS & COMMENTS
C3: PH. NO. | J3: I | K3: II | L3: III | M3: I | N3: II | O3: III | P3: I | Q3: II | R3: III | S3: I | T3: II | U3: III | V3: I | W3: II | X3: III | Y3: I | Z3: II | AA3: III | AB3: I | AC3: II | AD3: III | AE3: I | AF3: II | AG3: III | AH3: I | AI3: II | AJ3: III | AK3: I | AL3: II | AM3: III | AN3: I | AO3: II | AP3: III | AQ3: I | AR3: II | AS3: III | AT3: I | AU3: II | AV3: III | AW3: I | AX3: II | AY3: III | AZ3: I | BA3: II | BB3: III | BC3: I | BD3: II | BE3: III | BF3: I | BG3: II | BH3: III | BI3: I | BJ3: II | BK3: III | BL3: I | BM3: II | BN3: III | BO3: I | BP3: II | BQ3: III | BR3: I | BS3: II | BT3: III | BU3: I | BV3: II | BW3: III | BX3: I | BY3: II | BZ3: III | CA3: I | CB3: II | CC3: III
A4: =ROW()-3 -> 1 | B4: CHRIST INTERNATIONAL SCHOOL | C4: Pri.Vijayalakshmi | D4: 737374488 | G4: Thanjavur | H4: CBSE | I4: 700 | P4: P | AN4: P | AT4: P | CD4: =COUNTA(J4:CC4) -> 3 | CG4: MAR05-Last year order no changes FEB04-No changes this year OCT09-DISCUSS ABUT ORDER. | CH4: =IF(CD4<=0,"0",IF(CD4=1,"1",IF(CD4=2,"2",IF(CD4=3,"3",IF(CD4>=4,"4"))))) -> 3
A5: =ROW()-3 -> 2 | B5: Dr GS Kalyanasundaram Memorial School | C5: Anusha | F5: Kumbakonam | G5: Thanjavur | H5: CBSE | I5: 1848 | V5: P | CD5: =COUNTA(J5:CC5) -> 1 | CF5: NOV02-REQ | CG5: NOV02-SAMPLING November end | CH5: =IF(CD5<=0,"0",IF(CD5=1,"1",IF(CD5=2,"2",IF(CD5=3,"3",IF(CD5>=4,"4"))))) -> 1
A6: =ROW()-3 -> 3 | B6: KAMALA SUBRAMANIAM PUBLIC SCHOOL | C6: Ms Ponni | D6: 04362-227840 | E6: ksmsthanjavur@gmail.com | G6: Thanjavur | H6: CBSE | I6: 80 | P6: P | S6: P | AN6: P | AT6: P | AU6: P | AZ6: P | CD6: =COUNTA(J6:CC6) -> 6 | CF6: OCT26-REQ | CG6: APR11-Order finished MAR14-Order is under process MAR05-Books are seeing under process FEB04-known about order OCT26-SAMPLING DEC END. OCT09-F.UP VST. | CH6: =IF(CD6<=0,"0",IF(CD6=1,"1",IF(CD6=2,"2",IF(CD6=3,"3",IF(CD6>=4,"4"))))) -> 4
A7: =ROW()-3 -> 4 | B7: RADIANT INTERNATIONAL SCHOOL | C7: Pri.Vasanth | D7: 9626383627 | G7: Thanjavur | H7: CBSE | I7: 700 | S7: P | Y7: P | AN7: P | BR7: P | BS7: P | CD7: =COUNTA(J7:CC7) -> 5 | CE7: JAN24-Semester books 1to5 | CG7: JULY15-General visit JUL01-General visit FEB04- no changes JAN24-SPEC. GVN. OCT26-VST IN DEC. | CH7: =IF(CD7<=0,"0",IF(CD7=1,"1",IF(CD7=2,"2",IF(CD7=3,"3",IF(CD7>=4,"4"))))) -> 4
A8: =ROW()-3 -> 5 | B8: Thamarai international school | C8: Balaji | F8: Thanjore | G8: Thanjavur | H8: CBSE | I8: 3000 | V8: P | BR8: P | CD8: =COUNTA(J8:CC8) -> 2 | CF8: NOV06-REQ | CG8: JULY01-General visit NOV06-Wanted samples | CH8: =IF(CD8<=0,"0",IF(CD8=1,"1",IF(CD8=2,"2",IF(CD8=3,"3",IF(CD8>=4,"4"))))) -> 2
A9: =ROW()-3 -> 6 | B9: YAGAPPA INTERNATIONAL SCHOOL | C9: Mr Edward | D9: 9442112116 | E9: yistj@gmail.com | G9: Thanjavur | H9: CBSE | I9: 100 | S9: P | Y9: P | AQ9: P | BR9: P | CD9: =COUNTA(J9:CC9) -> 4 | CE9: FEB20-Drawing Ato5, speak and write 1to5 | CG9: JULY15-General visit FEB20-SPEC. GVN. JAN24-Not needed books OCT26-VST IN DEC. | CH9: =IF(CD9<=0,"0",IF(CD9=1,"1",IF(CD9=2,"2",IF(CD9=3,"3",IF(CD9>=4,"4"))))) -> 4
A11: =ROW()-4 -> 7 | B11: ALWIN MATRIC SCHOOL | G11: Thanjavur | H11: STATE | I11: 950 | P11: P | Y11: P | AN11: P | BC11: P | BR11: P | BU11: P | CD11: =COUNTA(J11:CC11) -> 6 | CE11: JAN24-Know it now 1to5, speak and write 1to5, easy computer 1to8 | CG11: JULY18-School visit for follow up JULY01-General visit JUN17-General visit FEB04-Books not finalized JAN24-SPEC. GVN. OCT09-DISCUSS ABUT BOOKS. | CH11: =IF(CD11<=0,"0",IF(CD11=1,"1",IF(CD11=2,"2",IF(CD11=3,"3",IF(CD11>=4,"4"))))) -> 4
A12: =ROW()-4 -> 8 | B12: AMALRAJ MATRIC HR SEC SCHOOL | E12: 1800 | G12: Thanjavur | H12: STATE | AT12: P | AW12: P | AZ12: P | BU12: P | CD12: =COUNTA(J12:CC12) -> 4 | CE12: APR11-Know it now gk 6to8 MAR20-Speak and write 1to5, Tamil handwriting 1to5, enjoy with colour Ato5 MAR05-Speak and write 1to8,gk, 6to8, hindi 1to8 Rashmi, computer books 1to8 | CG12: JULY18-General visit APR11-SPEC. GVN. MAR20-SPEC. GVN. MAR05-SPEC. GVN. | CH12: =IF(CD12<=0,"0",IF(CD12=1,"1",IF(CD12=2,"2",IF(CD12=3,"3",IF(CD12>=4,"4"))))) -> 4
A13: =ROW()-4 -> 9 | B13: AL MUBEEN MATRIC SCHOOL | C13: Ms Saroja | E13: 700 | G13: Thanjavur | H13: STATE | I13: 700 | AT13: P | CD13: =COUNTA(J13:CC13) -> 1 | CE13: MAR05-Speak and write 1to5, mili Tamil handwriting 1to5, rise and shine kg books | CG13: MAR05-SPE.C GVN. | CH13: =IF(CD13<=0,"0",IF(CD13=1,"1",IF(CD13=2,"2",IF(CD13=3,"3",IF(CD13>=4,"4"))))) -> 1
A14: =ROW()-4 -> 10 | B14: NAV BHARATH MATRIC SCHOOL | C14: Mr Johnson | D14: 04362-240776 | E14: navbharathtnj@gmail.com | G14: Thanjavur | H14: STATE | I14: 1300 | P14: P | S14: P | Y14: P | CD14: =COUNTA(J14:CC14) -> 3 | CG14: JAN24-Last year order no changes OCT26-COLLECT DETAILS. OCT09-F.UP VST. | CH14: =IF(CD14<=0,"0",IF(CD14=1,"1",IF(CD14=2,"2",IF(CD14=3,"3",IF(CD14>=4,"4"))))) -> 3
A15: =ROW()-4 -> 11 | B15: CS MATRIC | C15: Vasanthi | E15: 1320 | G15: Thanjavur | H15: STATE | I15: 1320 | AN15: P | AT15: P | AU15: P | AZ15: P | BR15: P | CD15: =COUNTA(J15:CC15) -> 5 | CE15: FEB04-My favourite gk 1to8, creative hands Ato5, speak and write 1to5,, computer genius 1to5 | CG15: JULY15-General visit APR11-asked about order confirmation MAR14-School visit and get details of order status MAR05-Books are seeing under process FEB04-SPEC. GVN | CH15: =IF(CD15<=0,"0",IF(CD15=1,"1",IF(CD15=2,"2",IF(CD15=3,"3",IF(CD15>=4,"4"))))) -> 4
A16: =ROW()-4 -> 12 | B16: LITTLE SCHOLARS MATRIC SCHOOL | C16: Mr Nandha sikamani | E16: 800 | G16: Thanjavur | H16: STATE | Y16: P | AZ16: P | CD16: =COUNTA(J16:CC16) -> 2 | CF16: JAN24-REQ | CG16: APR11-Order not finalized JAN24-Samples wanted February end | CH16: =IF(CD16<=0,"0",IF(CD16=1,"1",IF(CD16=2,"2",IF(CD16=3,"3",IF(CD16>=4,"4"))))) -> 2
A17: =ROW()-4 -> 13 | B17: Maxwell | C17: Dinesh Kumar | E17: 1200 | G17: Thanjavur | H17: STATE | Y17: P | AN17: P | CD17: =COUNTA(J17:CC17) -> 2 | CE17: FEB04-Basic grammar 1to8 JAN24-Rise and shine term book 1to5, speak and write 1to8 | CG17: FEB04-SPEC. GVN. JAN24-SPEC. GVN | CH17: =IF(CD17<=0,"0",IF(CD17=1,"1",IF(CD17=2,"2",IF(CD17=3,"3",IF(CD17>=4,"4"))))) -> 2
A18: =ROW()-4 -> 14 | B18: Sri matha Matric school | C18: Ms.Gowri | D18: 0435-2431566 | F18: Kumbakonam | G18: Thanjavur | H18: STATE | I18: 1000 | V18: P | AT18: P | CD18: =COUNTA(J18:CC18) -> 2 | CE18: MAR13-Know it now gk 1to5, inner circle 1to5, speak and write 1to8 | CG18: MAR13-SPEC. GVN. NOV06-Discuss our title | CH18: =IF(CD18<=0,"0",IF(CD18=1,"1",IF(CD18=2,"2",IF(CD18=3,"3",IF(CD18>=4,"4"))))) -> 2
A19: =ROW()-4 -> 15 | B19: VENKATESWARA MATRIC | C19: Pri.varadharajan | D19: 04362-223487 | G19: Thanjavur | H19: STATE | I19: 650 | S19: P | Y19: P | AN19: P | AT19: P | AU19: P | AW19: P | AZ19: P | CD19: =COUNTA(J19:CC19) -> 7 | CE19: FEB04-Rise and shine term book 1to5,smart english 6to8, maths 6to8, science 6to8, social 6to8 JAN24-Easy computer 1to8, value education 1to8, speak and write 1to8, drawing Ato5, | CG19: APR11-Order is under process MAR20-Books are seeing under process MAR14-School visit and collect details MAR05-Order is under process FEB04-SPEC. GVN. JAN24-SPEC. GVN. OCT26-VST IN JAN. | CH19: =IF(CD19<=0,"0",IF(CD19=1,"1",IF(CD19=2,"2",IF(CD19=3,"3",IF(CD19>=4,"4"))))) -> 4
A56: =ROW()-4 -> 52 | B56: INDIAN MARTICULAR SCHOOL | C56: SALIJA BAHNU | D56: 04362-247680 | G56: THANJAUR | H56: STATE | P56: P | CD56: =COUNTA(J56:CC56) -> 1 | CG56: OCT09-DISCUSS ABUT ORDER. | CH56: =IF(CD56<=0,"0",IF(CD56=1,"1",IF(CD56=2,"2",IF(CD56=3,"3",IF(CD56>=4,"4"))))) -> 1
A57: =ROW()-4 -> 53 | B57: DHARANI VIDYA MANDHIR CBSE SCHOOL | C57: Mr Vidyut | D57: 9578727026 | E57: dvmcbseschool@gmail.com | G57: Thanjavur | H57: CBSE | I57: 300 | AW57: P | CD57: =COUNTA(J57:CC57) -> 1 | CE57: MAR20-Hindi books 1to8, basic english grammar 1to5, rise and shine term book 1to5 | CG57: MAR20-SPEC. GVN. | CH57: =IF(CD57<=0,"0",IF(CD57=1,"1",IF(CD57=2,"2",IF(CD57=3,"3",IF(CD57>=4,"4"))))) -> 1
A58: =ROW()-4 -> 54 | B58: BEST MATRICULATION HR SC SCHOOL | C58: JAYA | E58: 1500 | G58: Thanjavur | H58: STATE | I58: 1500 | Y58: P | CD58: =COUNTA(J58:CC58) -> 1 | CG58: JAN24-NO CHANGE. | CH58: =IF(CD58<=0,"0",IF(CD58=1,"1",IF(CD58=2,"2",IF(CD58=3,"3",IF(CD58>=4,"4"))))) -> 1
A59: =ROW()-4 -> 55 | B59: NAV BHARATH MATRIC SCHOOL | C59: Mr Johnson | E59: 1300 | G59: Thanjavur | H59: STATE | AT59: P | CD59: =COUNTA(J59:CC59) -> 1 | CG59: MAR05-NO CHANGE. | CH59: =IF(CD59<=0,"0",IF(CD59=1,"1",IF(CD59=2,"2",IF(CD59=3,"3",IF(CD59>=4,"4"))))) -> 1
A60: =ROW()-4 -> 56 | B60: SANKARA VIDYALAYA | C60: Ms Sathya | D60: 9442996800 | E60: sankaravidyalayamyl@gmail.com | G60: Thanjavur | H60: STATE | I60: 1200 | S60: P | T60: P | Y60: P | CD60: =COUNTA(J60:CC60) -> 3 | CF60: NOV-20 REQ | CG60: NOV-20 WANT SPECIMEN IN DEC END OCT28-SCHOOL VST. OCT18-COLLECT DETAILS. | CH60: =IF(CD60<=0,"0",IF(CD60=1,"1",IF(CD60=2,"2",IF(CD60=3,"3",IF(CD60>=4,"4"))))) -> 3
A62: =ROW()-3 -> 59 | B62: KRISHNA PLAY SCHOOL | G62: THANJAVUR | H62: CBSE | P62: P | CD62: =COUNTA(J62:CC62) -> 1 | CG62: OCT09-DISCUSS ABUT ORDER. | CH62: =IF(CD62<=0,"0",IF(CD62=1,"1",IF(CD62=2,"2",IF(CD62=3,"3",IF(CD62>=4,"4"))))) -> 1
A69: 1 | B69: BISHOP DEVADOSS AMROSE VIDHYALAYA | C69: Fr.Christopher | D69: 6374417733 | G69: Thanjavur | H69: CBSE | I69: 1500 | CD69: =COUNTA(J69:CC69) -> 0 | CH69: =IF(CD69<=0,"0",IF(CD69=1,"1",IF(CD69=2,"2",IF(CD69=3,"3",IF(CD69>=4,"4"))))) -> 0
A70: 2 | B70: BLOSSOM PUBLIC SCHOOL | C70: Ms.Mery Shanthi | D70: 9442344741 | G70: Thanjavur | H70: CBSE | I70: 1573 | CD70: =COUNTA(J70:CC70) -> 0 | CH70: =IF(CD70<=0,"0",IF(CD70=1,"1",IF(CD70=2,"2",IF(CD70=3,"3",IF(CD70>=4,"4"))))) -> 0
A71: 4 | B71: DELTA PUBLIC SCHOOL | C71: Ms.Jeosphine | D71: 9626542716 | G71: Thanjavur | H71: CBSE | I71: 800 | CD71: =COUNTA(J71:CC71) -> 0 | CH71: =IF(CD71<=0,"0",IF(CD71=1,"1",IF(CD71=2,"2",IF(CD71=3,"3",IF(CD71>=4,"4"))))) -> 0
A72: 7 | B72: Dr GS Kalyanasundaram Memorial School | C72: Anusha | F72: Kumbakonam | G72: Thanjavur | H72: CBSE | I72: 1848 | CD72: =COUNTA(J72:CC72) -> 0 | CH72: =IF(CD72<=0,"0",IF(CD72=1,"1",IF(CD72=2,"2",IF(CD72=3,"3",IF(CD72>=4,"4"))))) -> 0
A73: 8 | B73: Dr GS Kalyanasundaram Memorial School | C73: Anusha | F73: Kumbakonam | G73: Thanjavur | H73: CBSE | I73: 1848 | CD73: =COUNTA(J73:CC73) -> 0 | CH73: =IF(CD73<=0,"0",IF(CD73=1,"1",IF(CD73=2,"2",IF(CD73=3,"3",IF(CD73>=4,"4"))))) -> 0
A74: 9 | B74: Dr GS Kalyanasundaram Memorial School | C74: Mr Breeze Pappachan | D74: 8870655163 | E74: drgsk.2007@yahoo.in | F74: Kumbakonam | G74: Thanjavur | H74: CBSE | I74: 1848 | CD74: =COUNTA(J74:CC74) -> 0 | CH74: =IF(CD74<=0,"0",IF(CD74=1,"1",IF(CD74=2,"2",IF(CD74=3,"3",IF(CD74>=4,"4"))))) -> 0
A75: 10 | B75: Dr GS Kalyanasundaram Memorial School | C75: Ms.Jayanthi | D75: 9841336644 | E75: drgsk.2007@yahoo.in | F75: Kumbakonam | G75: Thanjavur | H75: CBSE | I75: 1848 | CD75: =COUNTA(J75:CC75) -> 0 | CH75: =IF(CD75<=0,"0",IF(CD75=1,"1",IF(CD75=2,"2",IF(CD75=3,"3",IF(CD75>=4,"4"))))) -> 0
A76: 11 | B76: Dr GS Kalyanasundaram Memorial School | C76: Ms.Jayanthi | D76: 9841336644 | E76: drgsk.2007@yahoo.in | F76: Kumbakonam | G76: Thanjavur | H76: CBSE | I76: 1848 | CD76: =COUNTA(J76:CC76) -> 0 | CH76: =IF(CD76<=0,"0",IF(CD76=1,"1",IF(CD76=2,"2",IF(CD76=3,"3",IF(CD76>=4,"4"))))) -> 0
A77: 16 | B77: Thamarai international school | C77: Mr.Navin | F77: Thanjore | G77: Thanjavur | H77: CBSE | I77: 3000 | CD77: =COUNTA(J77:CC77) -> 0 | CH77: =IF(CD77<=0,"0",IF(CD77=1,"1",IF(CD77=2,"2",IF(CD77=3,"3",IF(CD77>=4,"4"))))) -> 0
A78: 17 | B78: Thamarai international school | C78: Mr.Navin | E78: nil | F78: Thanjore | G78: Thanjavur | H78: CBSE | I78: 3000 | CD78: =COUNTA(J78:CC78) -> 0 | CH78: =IF(CD78<=0,"0",IF(CD78=1,"1",IF(CD78=2,"2",IF(CD78=3,"3",IF(CD78>=4,"4"))))) -> 0
A79: 19 | B79: AL MUBEEN MATRIC SCHOOL | C79: Ms Saroja | D79: 9442190071 | E79: almubeenschool@gmail.com | G79: Thanjavur | H79: STATE | I79: 700 | CD79: =COUNTA(J79:CC79) -> 0 | CH79: =IF(CD79<=0,"0",IF(CD79=1,"1",IF(CD79=2,"2",IF(CD79=3,"3",IF(CD79>=4,"4"))))) -> 0
A80: 21 | B80: AMALRAJ MATRIC HR SEC SCHOOL | C80: Ms Brejet Amali | D80: 04362-260488 | E80: amalrajmhss@gmail.com | G80: Thanjavur | H80: STATE | I80: 1800 | CD80: =COUNTA(J80:CC80) -> 0 | CH80: =IF(CD80<=0,"0",IF(CD80=1,"1",IF(CD80=2,"2",IF(CD80=3,"3",IF(CD80>=4,"4"))))) -> 0
A81: 22 | B81: BEST MATRICULATION HR SC SCHOOL | C81: Ms Jaya | D81: 04362-268333 | E81: bestmhss@gmail.com | G81: Thanjavur | H81: STATE | I81: 1500 | CD81: =COUNTA(J81:CC81) -> 0 | CH81: =IF(CD81<=0,"0",IF(CD81=1,"1",IF(CD81=2,"2",IF(CD81=3,"3",IF(CD81>=4,"4"))))) -> 0
A82: 23 | B82: DHARANI MATRIC SCHOOL | C82: Mr Rajkumar | D82: 9578727026 | E82: dharanimatricmannai@gmail.com | G82: Thanjavur | H82: STATE | I82: 800 | CD82: =COUNTA(J82:CC82) -> 0 | CH82: =IF(CD82<=0,"0",IF(CD82=1,"1",IF(CD82=2,"2",IF(CD82=3,"3",IF(CD82>=4,"4"))))) -> 0
A83: 25 | B83: LITTLE ROSE MATRIC SCHOOL | C83: Mr Rajendran | D83: 9500533566 | E83: littlerosematricschool@gmail.com | G83: Thanjavur | H83: STATE | I83: 1400 | AZ83: P | CD83: =COUNTA(J83:CC83) -> 1 | CG83: JULY01-follow up | CH83: =IF(CD83<=0,"0",IF(CD83=1,"1",IF(CD83=2,"2",IF(CD83=3,"3",IF(CD83>=4,"4"))))) -> 1
A84: 26 | B84: LITTLE SCHOLARS MATRIC SCHOOL | C84: Mr Nandha sikamani | D84: 04362-259130 | E84: lsmhss.thanjavur@gmail.com | G84: Thanjavur | H84: STATE | I84: 800 | CD84: =COUNTA(J84:CC84) -> 0 | CH84: =IF(CD84<=0,"0",IF(CD84=1,"1",IF(CD84=2,"2",IF(CD84=3,"3",IF(CD84>=4,"4"))))) -> 0
...

Sheet TIRUCHIRAPPALLI
A1: TIRUCHIRAPPALLI , TRICHY
A2: SR. NO. | B2: NAME OF SCHOOL | C2: PRINCIPAL/TEACHER NAME | D2: CONT NO | E2: E. MAIL ID | F2: ADDRESS | G2: STATIONS | H2: BOARD | I2: STR | J2: SEP1ST | M2: SEP 2ND | P2: OCT1ST | S2: OCT 2ND | V2: 37196 | Y2: 37561 | AB2: DEC 1ST | AE2: DEC 2ND | AH2: JAN 1ST | AK2: JAN 2ND | AN2: FEB IST | AQ2: FEB IIND | AT2: MAR 1ST | AW2: MAR 2ND | AZ2: APR 1ST | BC2: APR2ND | BF2: MAY 1ST | BI2: MAY 2ND | BL2: JUN 1ST | BO2: JUN 2ND | BR2: JUL 1ST | BU2: JUL 2ND | BX2: AUG 1ST | CA2: AUG 2ND | CD2: C | CE2: SPECIMEN- GIVEN | CF2: SPECIMEN - REQ. | CG2: VISIT DETIALS & COMMENTS
C3: PH. NO. | J3: I | K3: II | L3: III | M3: I | N3: II | O3: III | P3: I | Q3: II | R3: III | S3: I | T3: II | U3: III | V3: I | W3: II | X3: III | Y3: I | Z3: II | AA3: III | AB3: I | AC3: II | AD3: III | AE3: I | AF3: II | AG3: III | AH3: I | AI3: II | AJ3: III | AK3: I | AL3: II | AM3: III | AN3: I | AO3: II | AP3: III | AQ3: I | AR3: II | AS3: III | AT3: I | AU3: II | AV3: III | AW3: I | AX3: II | AY3: III | AZ3: I | BA3: II | BB3: III | BC3: I | BD3: II | BE3: III | BF3: I | BG3: II | BH3: III | BI3: I | BJ3: II | BK3: III | BL3: I | BM3: II | BN3: III | BO3: I | BP3: II | BQ3: III | BR3: I | BS3: II | BT3: III | BU3: I | BV3: II | BW3: III | BX3: I | BY3: II | BZ3: III | CA3: I | CB3: II | CC3: III
A4: =ROW()-3 -> 1 | B4: Amirtha vidyalaya | F4: Retaivaikal road | G4: Tiruchirappalli | H4: CBSE | I4: 1500 | P4: P | S4: P | Y4: P | Z4: P | AB4: P | AE4: P | AF4: P | BF4: P | BL4: P | BO4: P | BU4: P | BV4: P | CD4: =COUNTA(J4:CC4) -> 12 | CE4: DEC10-Sanskrit books | CG4: JULY31-General visit JULY17- next follow up JUN26-General visit JUN02-follow up MAY07-Order finished DEC27-Books not decided DEC16-Books are gothrough DEC10-SPEC. GVN. NOV28-Books are seeing NOV25-December end decide OCT18-VST NOV END. OCT05-VST FOR ORDER. | CH4: =IF(CD4<=0,"0",IF(CD4=1,"1",IF(CD4=2,"2",IF(CD4=3,"3",IF(CD4>=4,"4"))))) -> 4
A5: =ROW()-3 -> 2 | B5: CARE SCHOOL | C5: Priya | D5: 9566239282 | G5: Tiruchirappalli | H5: CBSE | I5: 560 | M5: P | N5: P | AB5: P | AC5: P | AE5: P | AF5: P | AH5: P | AK5: P | AN5: P | BF5: P | BG5: P | BI5: P | BL5: P | BO5: P | BU5: P | BV5: P | BX5: P | CD5: =COUNTA(J5:CC5) -> 17 | CE5: JAN22-Grammar 1to8, science 6to8, speak and write 1to5, hindi writting 1to5, english english 1to8 | CF5: DEC24-REQ DEC16-REQ DEC13-REQ DEC02-REQ SEP30-REQ SEP21-REQ | CG5: AUG07-School visit JULY23- General visit JULY16-Visit school for follow up JUN20-General visit JUN11-General visit MAY22-Follow up MAY13-next year follow up MAY09-general visit FEB07-ORDER F.UP VST. JAN22-SPEC. GVN. JAN04-After Pongal books are seeing DEC24-Samples asked January DEC16-SAMPLING IN JAN. DEC13-SAMPLING IN JAN. DEC02-Books wanted on January SEP30-SAMPLING IN JAN. SEP21-SAMPLING IN JAN. | CH5: =IF(CD5<=0,"0",IF(CD5=1,"1",IF(CD5=2,"2",IF(CD5=3,"3",IF(CD5>=4,"4"))))) -> 4
A6: =ROW()-3 -> 3 | B6: Cauvery Global | C6: Book incharge | F6: ramalingam nagar.trichy cbse | G6: Tiruchirappalli | H6: CBSE | I6: 1050 | P6: P | S6: P | V6: P | W6: P | Y6: P | Z6: P | AA6: PP | AB6: P | AK6: P | AN6: P | AQ6: P | AW6: P | AZ6: P | BC6: P | BF6: P | BL6: P | BU6: P | BX6: P | CD6: =COUNTA(J6:CC6) -> 18 | CE6: APR05-Sanskrit books 1to5 MAR19-Know it now gk 1to8 FEB27-Smart english 1to8 course books and work book FEB06-EVs 1&2,kavya hindi 1to8, creative hands Ato5, Hindi writing books 1to8. JAN31-Conquer english 1to5, school 3to5,milli Tamil handwriting 1to5, easy computer 1to8, inside out gk 1to8, value education 1to8 | CF6: NOV27-REQ NOV25-REQ NOV19-REQ NOV18-REQ NOV16-REQ NOV12-REQ NOV07-REQ | CG6: AUG07-General visit JULY17-General visit JUN12-General visit MAY09-Order finished APR22-DISCUSS ORDER. APR05-SPEC. GVN. MAR19-SPEC. GVN FEB27-SEOPC GVN. FEB06-SPEC. GVN. JAN31-SPEC. GVN. DEC13-Samples asked December end NOV30-LST FINAL IN JAN. NOV27-December 2nd week NOV25-SAMPLING DEC 2ND WEEK. NOV19-December end NOV18-November end books wanted NOV16-SAMPLING IN December NOV12-SAMPLING IN December NOV07-SAMPLING November end OCT29-DETAIL COLELCT. OCT03-DISCUSS ABUT ORDER., | CH6: =IF(CD6<=0,"0",IF(CD6=1,"1",IF(CD6=2,"2",IF(CD6=3,"3",IF(CD6>=4,"4"))))) -> 4
A7: =ROW()-3 -> 4 | B7: CAUVERY INTERNATIONAL | C7: Ms.Priya | D7: 9597556849 | E7: cauveryintl@gmail.com | G7: Tiruchirappalli | H7: CBSE | I7: 900 | M7: P | AE7: P | AF7: P | AN7: P | AO7: P | BC7: P | BI7: P | BL7: P | BR7: P | BU7: P | CD7: =COUNTA(J7:CC7) -> 10 | CE7: FEB15-Nai Kiran hindi 1to8. FEB05-English conquer 1to8, science 6to8, maths 6to8, basic english grammar 1to8. | CF7: DEC18-REQ SEP23-REQ | CG7: JULY29-General visit JULY03-General visit JUN13-follow up MAY19-General visit APR23-OUR TITLE NOT SLECTED. FEB15-SPEC. GVN. FEB05-SPEC. GVN. DEC28-Asked non core books DEC18-Samples asked December end SEP23-SAMPLING IN JAN. | CH7: =IF(CD7<=0,"0",IF(CD7=1,"1",IF(CD7=2,"2",IF(CD7=3,"3",IF(CD7>=4,"4"))))) -> 4
A8: =ROW()-3 -> 5 | B8: KAMALA NIKETHAN | C8: Srithar | D8: 9790318676 | G8: Tiruchirappalli | H8: CBSE | I8: 3000 | AB8: P | AE8: P | AF8: P | AG8: P | AK8: P | BF8: P | BG8: P | BH8: P | BI8: P | BL8: P | BR8: P | BS8: P | CD8: =COUNTA(J8:CC8) -> 12 | CE8: DEC19-Map practice 9and 10& hindi | CF8: DEC02-Map practice approach | CG8: JULY14-given key answer JULY03-General visit JUN02-General visit MAY21-General visit MAY14-WANT teacher manual MAY10-General visit MAY02-given key book JAN27-Order finished DEC26-School visit for map book order DEC24-Follow up for order DEC19-SPEC. GVN. DEC02-SAMPLING IN DEC. | CH8: =IF(CD8<=0,"0",IF(CD8=1,"1",IF(CD8=2,"2",IF(CD8=3,"3",IF(CD8>=4,"4"))))) -> 4
A9: =ROW()-3 -> 6 | B9: MAHATMA GANDHI SCHOOL | C9: MRS. PODNA | G9: Tiruchirappalli | H9: CBSE | I9: 1050 | AE9: P | AF9: P | AH9: P | AK9: P | AZ9: P | BC9: P | BD9: P | BE9: PP | BF9: P | BG9: P | BI9: P | BJ9: P | BK9: PP | BO9: P | BP9: P | CD9: =COUNTA(J9:CC9) -> 15 | CE9: JAN10-Hindi 1to8 | CF9: DEC31-REQ DEC18-REQ | CG9: JUN25-General visit JUN20-Asked for digital content installation MAY30-General visit MAY29-Work Shop DONE WITH MRS. SARITA MAY22-program and finalize on29 th may MAY20-Asked for training program MAY15-Asked for orientation program MAY07-Work Shop asked may Last week APR29-teacher copy GVN APR28-teacher copy given APR23-WANT T. MANUL. APR17-given teachers copies APR07-Meet principal and given books JAN20-Books not finalized JAN10-SPEC. GVN. DEC31-Books asked January 1st week DEC18-SAMPLING IN JAN. | CH9: =IF(CD9<=0,"0",IF(CD9=1,"1",IF(CD9=2,"2",IF(CD9=3,"3",IF(CD9>=4,"4"))))) -> 4 | CI9: WORKSHOP
A10: =ROW()-3 -> 7 | B10: mont fort nursery & primary | C10: Brother.Amal Raj | D10: 0432-267367 | F10: manaparai trichy | G10: Tiruchirappalli | H10: CBSE | I10: 377 | M10: P | V10: P | Y10: P | AE10: P | AK10: P | AN10: P | BR10: P | BX10: P | CD10: =COUNTA(J10:CC10) -> 8 | CE10: FEB05-Health and physical education | CF10: JAN21-physical education books NOV09-REQ SEP23-REQ | CG10: AUG05-General visit JULY04-General visit FEB05-SPEC. GVN. JAN21-WANT SPEC. DEC28-SAMPLING AFTER PONGAL. NOV29-Books seeing on January ember month NOV09-SAMPLING Dec SEP23-SAMPLING IN MARCH. | CH10: =IF(CD10<=0,"0",IF(CD10=1,"1",IF(CD10=2,"2",IF(CD10=3,"3",IF(CD10>=4,"4"))))) -> 4
A11: =ROW()-3 -> 8 | B11: Monfort | C11: Leonardi | E11: 4000 | G11: Tiruchirappalli | H11: CBSE | I11: 4000 | AH11: P | AK11: P | BI11: P | BO11: P | BR11: P | CD11: =COUNTA(J11:CC11) -> 5 | CE11: JAN07-Computer 1to8, hindi books 1to5 JAN04-6 to 8 subject books | CG11: JULY08-next follow up JUN20- follow up MAY17-General visit JAN16- Order not finalized JAN07-SPEC. GVN. JAN04-SPEC. GVN. | CH11: =IF(CD11<=0,"0",IF(CD11=1,"1",IF(CD11=2,"2",IF(CD11=3,"3",IF(CD11>=4,"4"))))) -> 4
A12: =ROW()-3 -> 9 | B12: ORCHARD CBSE SCHOOL | C12: Ms.Silvi | D12: 0431-2457994 | E12: orchardschool@gmail.com | G12: Tiruchirappalli | H12: CBSE | I12: 850 | AB12: P | AE12: P | AF12: P | AK12: P | AL12: P | AQ12: P | AR12: P | AT12: P | AU12: P | AV12: P | AZ12: P | BF12: P | BG12: P | BH12: P | BL12: P | BO12: P | BP12: P | BQ12: P | BR12: P | BU12: P | CD12: =COUNTA(J12:CC12) -> 20 | CE12: FEB25-Modern science and technology 1to5 JAN21-Grammar 1to8, science 6to8, conquer english 1to8, kavya hindi 1to8, map practice 6to8. | CF12: JAN17-REQ DEC24-REQ DEC19-Subject books 6to8 DEC03-Books asked 6to8 | CG12: JULY25-Asked modern science One copy JULY04-Damage book replace JUN25-ebook installation JUN19-get details of defects of books JUN17-Meet principal for any digital content JUN10-orders and follow up MAY14-teacher manual MAY06-DISCUSS ABUT T. TRAINING. MAY02-F.UP VST. APR08-given teachers copies MAR12-Order finished MAR08-Order is under process MAR04-Books not finalized under process FEB25-SPEC GVN, FEB17-know about our status of order JAN21-SPE.C GVN. JAN17-SAMPLINGA FTER PONGAL. DEC24- Asked subject books DEC19-WANT SPEC. DEC03-WANT SPEC. | CH12: =IF(CD12<=0,"0",IF(CD12=1,"1",IF(CD12=2,"2",IF(CD12=3,"3",IF(CD12>=4,"4"))))) -> 4
A13: =ROW()-3 -> 10 | B13: rajaji vidyalaya. | C13: Karthik | F13: thennur trichy | G13: Tiruchirappalli | H13: CBSE | I13: 887 | M13: P | N13: P | P13: P | Q13: P | S13: P | T13: P | V13: P | W13: P | Y13: P | Z13: P | AB13: P | AE13: P | AF13: P | AH13: P | AI13: P | AK13: P | AL13: P | AM13: P | BC13: P | BD13: P | BF13: P | BG13: P | BI13: P | BJ13: P | BK13: PP | BL13: P | BM13: P | BO13: P | BR13: P | BU13: P | BX13: P | CD13: =COUNTA(J13:CC13) -> 31 | CE13: JAN20-Science 6to8, social 6to8, maths 6to8, english 6to8, grammar 1to8. JAN11-Kg books, patterns semester 1 to 5, | CF13: JAN04-Subject books,kg books DEC31-REQ DEC16-Kg books and 7and 8 DEC15-REQ NOV27-REQ NOV18-REQ NOV13-REQ NOV07-REQ OCT01-REQ SEP30-REQ SEP20-REQ | CG13: AUG07-General visit JULY31-General visit JULY08-General visit JUN20-General visit JUN03-teacher copy GVN. JUN02-order next year MAY30-follow up MAY28-T. COPY GVN. MAY23-follow up MAY17-WANT T. MNAUL. MAY13-Asked for any training program MAY06-DISCUSS T. TRAING . APR28- given maths teacher manual APR16-Asked teacher copy JAN31-Order realised JAN30-Order finalized JAN20-SPEC. GVN. JAN11-SPEC. GVN. JNA04-WANT SPEC DEC31-SAMPLING AFTER PONGAL. DEC16-WANT SPEC. DEC15-SAMPLING JAN 1ST WEEK. NOV27-December month wanted books NOV18-SAMPLING Ask December NOV13-Give on December NOV07-SAMPLING December 1st week OCT29-SCHOOL VST. OCT22-VST NOV END. OCT15-F.UP VST. OCT01-SAMPLING NOV END. SEP30-SAMPLING IN JAN. SEP20-SAMPLING IN DEC. | CH13: =IF(CD13<=0,"0",IF(CD13=1,"1",IF(CD13=2,"2",IF(CD13=3,"3",IF(CD13>=4,"4"))))) -> 4
A14: =ROW()-3 -> 11 | B14: RAJAM KRISHNAMOORTHY PUBLIC SCHOOL | C14: Mr.Hari | E14: krishnamorthypublicschool@gmail.com | G14: Tiruchirappalli | H14: CBSE | I14: 150 | P14: P | S14: P | AH14: P | AK14: P | AN14: P | AQ14: P | AR14: P | AW14: P | AZ14: P | BA14: P | BC14: P | BD14: P | BF14: P | BR14: P | CD14: =COUNTA(J14:CC14) -> 14 | CE14: FEB25-Computer books 9and10 FEB10-6th social, science,7&8 science JAN31-Basic english grammar 1to8 | CG14: JULY08- General visit MAY08-Order finished APR23-ORDER IS NOT FINALISED. APR22-ORDER TITLE NOT SLECTED. APR15-Order not finalized APR05-Order is under process MAR27-Order is under process FEB25-SPEC. GVN. FEB19-Orders finalized FEB10-SPEC. GVN JAN31-WANT SEPC. JAN07-Visit for order status OCT18-VST DEC 1ST WEEK. OCT05-VST & MEET OFFICE INCHARGE. | CH14: =IF(CD14<=0,"0",IF(CD14=1,"1",IF(CD14=2,"2",IF(CD14=3,"3",IF(CD14>=4,"4"))))) -> 4
A15: =ROW()-3 -> 12 | B15: Sacred heart cbse | C15: Ilaiyaraja | F15: Mathur | G15: Tiruchirappalli | H15: CBSE | I15: 1000 | M15: P | N15: P | P15: P | Q15: P | S15: P | T15: P | V15: P | Y15: P | AB15: P | AC15: P | AE15: P | BF15: P | BI15: P | BJ15: P | BK15: P | BL15: P | BO15: P | BP15: P | BR15: P | BS15: P | BU15: P | CD15: =COUNTA(J15:CC15) -> 21 | CE15: DEC18-*Computer books 1to5 DEC10-Computer AI 9&10 DEC02-Grammar 1to8 Gk 1 to 8 | CF15: NOV02-REQ SEP28-REQ SEP20-REQ | CG15: JULY28-GNRAL VST. JULY14-General visit JULY08-Visit school for follow up JUN28-follow up JUN23-General visit JUN10-asked for next year promotion MAY31-Follow up MAY23-follow up MAY19-General visit MAY03-F.UP VST. DEC18-SPEC. GVN. DEC10-SPEC. GVN. DEC02-SPEC. GVN. NOV28-SAMPLING December 2nd week NOV02-SAMPLING NOV END. OCT30-VST NOV 1ST WEKE. OCT23-DISCUSS ABUT BOOKS. OCT08-MEET BOOK INCHARGE. OCT01-DISCUSS WITH BOOK INCHARGE. SEP28-SAMPLING IN JAN. SEP20-SAMPLING IN FEB. | CH15: =IF(CD15<=0,"0",IF(CD15=1,"1",IF(CD15=2,"2",IF(CD15=3,"3",IF(CD15>=4,"4"))))) -> 4
A16: =ROW()-3 -> 13 | B16: Samadh School | C16: Mr. chakco Nithya | D16: 9942810251 | E16: samadhschool@tri.com | F16: kajamalai.trichy | G16: Tiruchirappalli | H16: CBSE | I16: 1200 | M16: P | S16: P | V16: P | Y16: P | AB16: P | AE16: P | AF16: P | BI16: P | BO16: P | BU16: P | BX16: P | CD16: =COUNTA(J16:CC16) -> 11 | CE16: DEC19-Hindi books DEC07-Hindi , subject 6to8,art and craft | CF16: NOV19-REQ NOV07-REQ SEP20-REQ | CG16: AUG04-General visit JULY19-General visit JUN23-General visit MAY24-follow up DEC26-Follow up for order DEC19-SPEC. GVN. DEC07-SPEC. GVN. NOV19-Books wanted on February NOV7-SAMPLING IN DEC. OCT22-SAMPLING IN DEC. SEP20-SAMPLING IN FEB. | CH16: =IF(CD16<=0,"0",IF(CD16=1,"1",IF(CD16=2,"2",IF(CD16=3,"3",IF(CD16>=4,"4"))))) -> 4
A17: =ROW()-3 -> 14 | B17: Santhanam Vidhyalaya | C17: Mrs.padma srinivasan | D17: 9443302526 | E17: santanamvidyalaya@gmail.com | F17: murugan talkies road | G17: Tiruchirappalli | H17: CBSE | I17: 530 | M17: P | P17: P | S17: P | V17: P | W17: P | BI17: P | BJ17: P | BL17: P | BM17: P | BO17: P | BU17: P | CD17: =COUNTA(J17:CC17) -> 11 | CE17: JUN03-Sanskrit books NOV13-Maths, science for(7&8) | CF17: NOV07-REQ | CG17: JULY16-General visit JUN19-DISCUSS about Sanskrit order JUN05-General visit JUN03-SPEC. GVN. MAY31-General visit MAY19-get details of selected books NOV19-Discuss with our title NOV13-SPEC. GVN. NOV07- Month of December OCT17-VST IN NOV. OCT01-DISCUSS ABUT ORDER. SEP18-VST AFTER PONGAL. | CH17: =IF(CD17<=0,"0",IF(CD17=1,"1",IF(CD17=2,"2",IF(CD17=3,"3",IF(CD17>=4,"4"))))) -> 4
A18: =ROW()-3 -> 15 | B18: SIVANANDHA BALA | C18: Mrs.Revathy | D18: 9443735437 | E18: sivanandabalalaya@radiffmaul.com | G18: Tiruchirappalli | H18: CBSE | I18: 800 | M18: P | P18: P | AB18: P | AE18: P | AF18: P | AG18: P | AH18: P | AK18: P | AT18: P | AW18: P | AZ18: P | BL18: P | BM18: P | BR18: P | CD18: =COUNTA(J18:CC18) -> 14 | CE18: JUN12- saras hindi book APR05-Speak and write 1to5, mili Tamil handwriting 1to5, ncert assignment english, maths 1to5 MAR22-Know it now gk 1to5 MAR2-Inner circle 1to8, gk 1to8, hindi books 1to8 nai Kiran | CF18: DEC27-REQ DEC18-REQ DEC03-REQ SEP24-REQ | CG18: JULY09-General visit JUN14-Order visit JUN12-SPEC. GVN. APR05-SPEC GVN. MAR22-SPEC. GVN. MAR12-SPEC. GVN. JAN22-Wanted subject books JAN07-School visit DEC27-SAMPLING IN JAN. DEC19-SAMPLING IN JAN MNTH. DEC18-Wanted December end DEC03-SAMPLING IN JAN. OCT03-DISCUSS ABUT ORDER. SEP24-SAMPLING IN JAN. | CH18: =IF(CD18<=0,"0",IF(CD18=1,"1",IF(CD18=2,"2",IF(CD18=3,"3",IF(CD18>=4,"4"))))) -> 4
A19: =ROW()-3 -> 16 | B19: Sowma Public School | C19: ms.epsiba | D19: 848937685 | E19: sowmapublicschool@gmail.com | F19: viralimalai road.trichy | G19: Tiruchirappalli | H19: CBSE | I19: 625 | V19: P | Y19: P | AE19: P | AK19: P | AN19: P | AT19: P | AW19: P | AZ19: P | BF19: P | BL19: P | BR19: P | BS19: P | BT19: P | BX19: P | CD19: =COUNTA(J19:CC19) -> 14 | CE19: JAN21-Conquer english 1to8, science 7to8, speak and write 1to8, hindi books 1to8, know it now 1to8, grammar 1to8 | CF19: DEC28-REQ NOV29-REQ | CG19: AUG07-General visit JULY08-General visit JULY12-General visit JULY04-General visit JUN13-General visit MAY10-General visit APR02-Order is finished MAR27-Order finalized MAR08-Order is finalized FEB05-Books not seeing for annual day function JAN21-SPEC. GVN. DEC28-SAMPLING IN JAN. NOV29-Books wanted on December month NOV09-Book seen on November end | CH19: =IF(CD19<=0,"0",IF(CD19=1,"1",IF(CD19=2,"2",IF(CD19=3,"3",IF(CD19>=4,"4"))))) -> 4
A20: =ROW()-3 -> 17 | B20: sri vageesha vidyashram | C20: Ananthan | F20: mellur road.trichy | G20: Tiruchirappalli | H20: CBSE | I20: 1500 | P20: P | Q20: P | T20: P | V20: P | W20: P | BF20: P | BI20: P | BL20: P | BO20: P | BU20: P | CD20: =COUNTA(J20:CC20) -> 10 | CE20: OCT24-MATH , HINDI , SCI 6-8 | CF20: OCT01-REQ | CG20: JULY30-General visit JUN23-General visit JUN11-General visit MAY21-next year follow up MAY08-General visit NOV12-Explain about the books NOV07-Books are seeing OCT24-SPEC. GVN. OCT08-VST & MEET PRINCIPAL. OCT01-SAMPLING OCT END. | CH20: =IF(CD20<=0,"0",IF(CD20=1,"1",IF(CD20=2,"2",IF(CD20=3,"3",IF(CD20>=4,"4"))))) -> 4
A21: =ROW()-3 -> 18 | B21: ST .JOHN OF ARC | C21: Ms.renuka | D21: 8056898155 | E21: stjohn@yahoo.com | G21: Tiruchirappalli | H21: CBSE | I21: 280 | M21: P | S21: P | AB21: P | AC21: P | BR21: P | CD21: =COUNTA(J21:CC21) -> 5 | CE21: DEC12-Computer AI books DEC03-Computer AI 6to8 | CF21: SEP24-REQ | CG21: JULY04-General visit DEC12-SPEC. GVN. DEC03-WANT SPEC. OCT19-VST IN NOV. SEP24-SAMPLING IN JAN. | CH21: =IF(CD21<=0,"0",IF(CD21=1,"1",IF(CD21=2,"2",IF(CD21=3,"3",IF(CD21>=4,"4"))))) -> 4
A22: =ROW()-3 -> 19 | B22: ST JAMES ACADEMY | C22: Wilfred | G22: Tiruchirappalli | H22: CBSE | I22: 517 | AB22: P | AE22: P | AF22: P | AG22: P | BL22: P | BO22: P | BX22: P | CD22: =COUNTA(J22:CC22) -> 7 | CE22: DEC19-EVS books 1&2 DEC02-Let's talk 1 to 5 | CG22: AUG01-Visit school for follow up JUN26-General visit JUN10-General visit DEC31-Books not finalized DEC26-January month books finalizing DEC19-SPEC. GVN. DEC02-SPEC. GVN. | CH22: =IF(CD22<=0,"0",IF(CD22=1,"1",IF(CD22=2,"2",IF(CD22=3,"3",IF(CD22>=4,"4"))))) -> 4
A23: =ROW()-3 -> 20 | B23: ST PATTRICAS ACADEMY | C23: father ramesh | D23: 948808469 | G23: Tiruchirappalli | H23: CBSE | I23: 349 | AB23: P | AC23: P | AE23: P | AF23: P | AK23: P | AQ23: P | AR23: P | AZ23: P | BL23: P | BR23: P | CD23: =COUNTA(J23:CC23) -> 10 | CE23: JAN23-Ncert assignment 6to8, English, science, maths | CF23: DEC16-kg& subject books DEC15-REQ DEC03-Semester books | CG23: JULY12-General visit JUN02-order follow up APR02-Order finished FEB27-Order finished FEB21-Order realised JAN23-SPEC. GVN. DEC26-School visit for details DEC16-WANT SPEC. DEC15-SAMPLING IN JAN. DEC03- WANT SPEC. | CH23: =IF(CD23<=0,"0",IF(CD23=1,"1",IF(CD23=2,"2",IF(CD23=3,"3",IF(CD23>=4,"4"))))) -> 4
A24: =ROW()-3 -> 21 | B24: VIGNESH PUBLIC SCHOOL | C24: Mr.Dhayanadhan | D24: 8973055577 | E24: vignesh_@hahoo.com | G24: Tiruchirappalli | H24: CBSE | I24: 900 | M24: P | N24: P | P24: P | S24: P | T24: P | U24: P | V24: P | Y24: P | Z24: P | AA24: P | AB24: P | AC24: P | BI24: P | BR24: P | BU24: P | BX24: P | CD24: =COUNTA(J24:CC24) -> 16 | CE24: DEC12-gk 1to8 NOV23-Grammar given NOV13-Basic English grammar and composition | CF24: SEP30-REQ SEP25-REQ | CG24: AUG01- follow up JULY30-General visit JULY09-General visit MAY20-General visit DEC12-SPEC. GVN. DEC07- Books are gothrough and verifying NOV28-Grammar book follow up NOV25-Books are seeing NOV23-SPEC. GVN. NOV13-SPEC. GVN. OCT28-VST & MEET PRINCIPAL. OCT24-VST IN NOV. OCT19-VST NOV 1ST WEEK. OCT03-VST NOV END. SEP30-SAMPLING IN JAN. SEP25-SAMPLING IN JAN. | CH24: =IF(CD24<=0,"0",IF(CD24=1,"1",IF(CD24=2,"2",IF(CD24=3,"3",IF(CD24>=4,"4"))))) -> 4
A25: =ROW()-3 -> 22 | B25: Vivekananda vidyalaya | C25: Thenmozhi | E25: 900 | G25: Tiruchirappalli | H25: CBSE | AB25: P | AE25: P | AK25: P | AL25: P | BF25: P | BL25: P | BO25: P | BU25: P | CD25: =COUNTA(J25:CC25) -> 8 | CE25: DEC10-English & maths assignment 1to3. | CG25: JULY30-Follow up JUN23-General visit JUN05-General visit MAY13-General visit JAN27-Order finalized JAN20-Visit for Assignment order DEC16-Books Not decided DEC10-SPEC. GVN. | CH25: =IF(CD25<=0,"0",IF(CD25=1,"1",IF(CD25=2,"2",IF(CD25=3,"3",IF(CD25>=4,"4"))))) -> 4
A27: =ROW()-4 -> 23 | B27: ARNOLD SCHOOL | G27: Tiruchirappalli | H27: STATE | I27: 550 | M27: P | BC27: P | CD27: =COUNTA(J27:CC27) -> 2 | CG27: APR22-ORDER TITLE SLECTED. SEP27-LST FINAL APRIL. | CH27: =IF(CD27<=0,"0",IF(CD27=1,"1",IF(CD27=2,"2",IF(CD27=3,"3",IF(CD27>=4,"4"))))) -> 2
